2023-02-01 16:06:11   Arguments: Namespace(Ensembel=False, aggregation='netvlad', aggregation2='netvlad', backbone='resnet18conv4', brightness=0, cache_refresh_rate=1000, contrast=0, criterion='triplet', dataset_name='pitts30k', datasets_folder='/content/drive/MyDrive/MLDL/datasets_vg', device='cuda', efficient_ram_testing=False, epochs_num=10, fc_output_dim=None, freeze_te=None, horizontal_flip=False, hue=0, infer_batch_size=16, l2='before_pool', lr=0.0001, lr_crn_layer=0.005, lr_crn_net=0.0005, majority_weight=0.01, margin=0.1, mining='partial', neg_samples_num=1000, negs_num_per_query=10, netvlad_clusters=64, num_workers=2, off_the_shelf='imagenet', optim='AdamW', patience=3, pca_dataset_folder=None, pca_dim=None, pretrain='imagenet', queries_per_epoch=5000, rand_perspective=0, random_resized_crop=0, random_rotation=0, recall_values=[1, 5, 10, 20], resize=[480, 640], resume=None, resume2=None, saturation=0, save_dir='/content/drive/MyDrive/MLDL/results/AdamW3/2023-02-01_16-06-10', seed=0, test_method='hard_resize', train_batch_size=4, train_positives_dist_threshold=10, trunc_te=None, val_positive_dist_threshold=25, weight_decay=0.05)
2023-02-01 16:06:11   The outputs are being saved in /content/drive/MyDrive/MLDL/results/AdamW3/2023-02-01_16-06-10
2023-02-01 16:06:11   Using 1 GPUs and 2 CPUs
2023-02-01 16:08:33   There are 96 queries without any positives within the training set. They won't be considered as they're useless for training.
2023-02-01 16:08:33   Train query set: < TripletsDataset, pitts30k - #database: 10000; #queries: 7320 >
2023-02-01 16:10:25   Val set: < BaseDataset, pitts30k - #database: 10000; #queries: 7608 >
2023-02-01 16:12:28   Test set: < BaseDataset, pitts30k - #database: 10000; #queries: 6816 >
2023-02-01 16:14:44   Output dimension of the model is 16384, with 17.27 GFLOPs
2023-02-01 16:14:44   Start training epoch: 00
2023-02-01 20:41:54   
Traceback (most recent call last):
  File "/usr/lib/python3.8/threading.py", line 306, in wait
    gotit = waiter.acquire(True, timeout)
KeyboardInterrupt

During handling of the above exception, another exception occurred:

Traceback (most recent call last):
  File "/usr/lib/python3.8/queue.py", line 179, in get
    self.not_empty.wait(remaining)
  File "/usr/lib/python3.8/threading.py", line 306, in wait
    gotit = waiter.acquire(True, timeout)
KeyboardInterrupt

During handling of the above exception, another exception occurred:

Traceback (most recent call last):
  File "train.py", line 123, in <module>
    triplets_ds.compute_triplets(args, model)
  File "/content/drive/MyDrive/MLDL/deep-visual-geo-localization-benchmark-main/datasets_ws.py", line 248, in compute_triplets
    self.compute_triplets_partial(args, model)
  File "/content/drive/MyDrive/MLDL/deep-visual-geo-localization-benchmark-main/datasets_ws.py", line 372, in compute_triplets_partial
    cache = self.compute_cache(args, model, subset_ds, cache_shape=(len(self), args.features_dim))
  File "/content/drive/MyDrive/MLDL/deep-visual-geo-localization-benchmark-main/datasets_ws.py", line 265, in compute_cache
    for images, indexes in tqdm(subset_dl, ncols=100):
  File "/usr/local/lib/python3.8/dist-packages/tqdm/std.py", line 1195, in __iter__
    for obj in iterable:
  File "/usr/local/lib/python3.8/dist-packages/torch/utils/data/dataloader.py", line 628, in __next__
    data = self._next_data()
  File "/usr/local/lib/python3.8/dist-packages/torch/utils/data/dataloader.py", line 1316, in _next_data
    idx, data = self._get_data()
  File "/usr/local/lib/python3.8/dist-packages/torch/utils/data/dataloader.py", line 1272, in _get_data
    success, data = self._try_get_data()
  File "/usr/local/lib/python3.8/dist-packages/torch/utils/data/dataloader.py", line 1120, in _try_get_data
    data = self._data_queue.get(timeout=timeout)
  File "/usr/lib/python3.8/queue.py", line 182, in get
    return item
  File "/usr/lib/python3.8/threading.py", line 250, in __exit__
    return self._lock.__exit__(*args)
RuntimeError: release unlocked lock

